<?xml version="1.0" ?>
<!-- =================================================================================== -->
<!-- |    This document was autogenerated by xacro from ur5.urdf.xacro                 | -->
<!-- |    EDITING THIS FILE BY HAND IS NOT RECOMMENDED                                 | -->
<!-- =================================================================================== -->
<robot name="ur5">
  <!-- properties of the UR5 robot -->
  <!-- cyldenrical inertia for approximation for the link inertias -->
  <!-- <xacro:macro name="cylinder_inertial" params="radius length mass *origin">

    <inertial>
      <mass value="${mass}" />
      <insert_block name="origin" />
      <inertia ixx="${0.0833333 * mass * (3 * radius * radius + length * length)}" ixy="0.0" ixz="0.0" iyy="${0.0833333 * mass * (3 * radius * radius + length * length)}" iyz="0.0" izz="${0.5 * mass * radius * radius}" />
    </inertial>
    
  </xacro:macro> -->
  <!-- the ur5_arm element -->
  <!-- <xacro:include filename="$(find ur5_description)/robots/ur5_gripper.xacro" /> -->
  <!-- fix the robot to the Gazebo world coordinate system -->
  <link name="world"/>
  <joint name="robot_to_world" type="fixed">
    <parent link="world"/>
    <child link="ur5_link0"/>
    <origin rpy="0.0 0.0 0.0" xyz="0.0 0.0 0.0"/>
    <dynamics damping="0.0"/>
  </joint>
  <!-- link 0 -->
  <!-- base link -->
  <link name="ur5_link0">
    <visual>
      <geometry>
        <mesh filename="package://ur5_description/meshes/visual/link0.dae"/>
      </geometry>
      <material name="LightGrey">
        <color rgba="0.7 0.7 0.7 1.0"/>
      </material>
    </visual>
    <collision>
      <geometry>
        <mesh filename="package://ur5_description/meshes/collision/link0.stl"/>
      </geometry>
    </collision>
    <!-- <cylinder_inertial radius="0.06" length="0.05" mass="${base_mass}">
        <origin xyz="0.0 0.0 0.0" rpy="0 0 0" />
      </cylinder_inertial> -->
    <inertial>
      <mass value="4.0"/>
      <inertia ixx="0.004433" ixy="0.0" ixz="0.0" iyy="0.00443333156" iyz="0.0" izz="0.0072"/>
    </inertial>
  </link>
  <!-- joint1 connects link0 and link1 -->
  <joint name="ur5_joint1" type="revolute">
    <parent link="ur5_link0"/>
    <child link="ur5_link1"/>
    <origin rpy="0.0 0.0 0.0" xyz="0.0 0.0 0.089159"/>
    <axis xyz="0 0 1"/>
    <!-- <limit lower="-3.14" upper="3.14" effort="150.0" velocity="3.15" /> -->
    <limit effort="150.0" lower="-3.141592653589793" upper="3.141592653589793" velocity="3.141592653589793"/>
    <dynamics damping="0.4" friction="0.0"/>
  </joint>
  <!-- link 1 -->
  <!-- shoulder link -->
  <link name="ur5_link1">
    <visual>
      <geometry>
        <mesh filename="package://ur5_description/meshes/visual/link1.dae"/>
      </geometry>
      <material name="LightGrey">
        <color rgba="0.7 0.7 0.7 1.0"/>
      </material>
    </visual>
    <collision>
      <geometry>
        <mesh filename="package://ur5_description/meshes/collision/link1.stl"/>
      </geometry>
    </collision>
    <!-- <cylinder_inertial radius="0.06" length="0.15" mass="${shoulder_mass}">
        <origin xyz="0.0 0.0 0.0" rpy="0 0 0" />
      </cylinder_inertial> -->
    <inertial>
      <mass value="3.7"/>
      <inertia ixx="0.010267495893" ixy="0.0" ixz="0.0" iyy="0.010267495893" iyz="0.0" izz="0.00666"/>
      <origin rpy="0.0 0.0 0.0" xyz="0.0 0.00193 -0.02561"/>
    </inertial>
  </link>
  <!-- joint2 connects link1 and link2 -->
  <joint name="ur5_joint2" type="revolute">
    <parent link="ur5_link1"/>
    <child link="ur5_link2"/>
    <origin rpy="0.0 1.5707963267948966 0.0" xyz="0.0 0.13585 0.0"/>
    <axis xyz="0 1 0"/>
    <!-- <limit lower="-3.14" upper="3.14" effort="150.0" velocity="3.15" /> -->
    <limit effort="150.0" lower="-3.141592653589793" upper="3.141592653589793" velocity="3.141592653589793"/>
    <dynamics damping="0.4" friction="0.0"/>
  </joint>
  <!-- link 2 -->
  <!-- upper arm link -->
  <link name="ur5_link2">
    <visual>
      <geometry>
        <mesh filename="package://ur5_description/meshes/visual/link2.dae"/>
      </geometry>
      <material name="LightGrey">
        <color rgba="0.7 0.7 0.7 1.0"/>
      </material>
    </visual>
    <collision>
      <geometry>
        <mesh filename="package://ur5_description/meshes/collision/link2.stl"/>
      </geometry>
    </collision>
    <!-- <cylinder_inertial radius="0.06" length="0.56" mass="${upper_arm_mass}">
        <origin xyz="0.0 0.0 0.28" rpy="0 0 0" />
      </cylinder_inertial> -->
    <inertial>
      <mass value="8.393"/>
      <inertia ixx="0.22689067591036" ixy="0.0" ixz="0.0" iyy="0.22689067591036" iyz="0.0" izz="0.0151074"/>
      <origin rpy="0.0 0.0 0.0" xyz="0.0 -0.024201 0.2125"/>
    </inertial>
  </link>
  <!-- joint3 connects link2 and link3 -->
  <joint name="ur5_joint3" type="revolute">
    <parent link="ur5_link2"/>
    <child link="ur5_link3"/>
    <origin rpy="0.0 0.0 0.0" xyz="0.0 -0.1197 0.425"/>
    <axis xyz="0 1 0"/>
    <!-- <limit lower="-3.14" upper="3.14" effort="150.0" velocity="3.15" /> -->
    <limit effort="150.0" lower="-3.141592653589793" upper="3.141592653589793" velocity="3.141592653589793"/>
    <dynamics damping="0.4" friction="0.0"/>
  </joint>
  <!-- link 3 -->
  <!-- forearm link -->
  <link name="ur5_link3">
    <visual>
      <geometry>
        <mesh filename="package://ur5_description/meshes/visual/link3.dae"/>
      </geometry>
      <material name="LightGrey">
        <color rgba="0.7 0.7 0.7 1.0"/>
      </material>
    </visual>
    <collision>
      <geometry>
        <mesh filename="package://ur5_description/meshes/collision/link3.stl"/>
      </geometry>
    </collision>
    <!-- <cylinder_inertial radius="0.06" length="0.5" mass="${forearm_mass}">
        <origin xyz="0.0 0.0 0.25" rpy="0 0 0" />
      </cylinder_inertial> -->
    <inertial>
      <mass value="2.275"/>
      <origin rpy="0.0 0.0 0.0" xyz="0.0 0.0265 0.11993"/>
      <inertia ixx="0.049443313556" ixy="0.0" ixz="0.0" iyy="0.049443313556" iyz="0.0" izz="0.004095"/>
    </inertial>
  </link>
  <!-- joint4 connects link3 and link4 -->
  <joint name="ur5_joint4" type="revolute">
    <parent link="ur5_link3"/>
    <child link="ur5_link4"/>
    <origin rpy="0.0 1.5707963267948966 0.0" xyz="0.0 0.0 0.39225"/>
    <axis xyz="0 1 0"/>
    <!-- <limit lower="-3.14" upper="3.14" effort="28.0" velocity="3.2" /> -->
    <limit effort="28.0" lower="-3.141592653589793" upper="0.7853981633974483" velocity="3.141592653589793"/>
    <dynamics damping="0.3" friction="0.0"/>
  </joint>
  <!-- link 4 -->
  <link name="ur5_link4">
    <visual>
      <geometry>
        <mesh filename="package://ur5_description/meshes/visual/link4.dae"/>
      </geometry>
      <material name="LightGrey">
        <color rgba="0.7 0.7 0.7 1.0"/>
      </material>
    </visual>
    <collision>
      <geometry>
        <mesh filename="package://ur5_description/meshes/collision/link4.stl"/>
      </geometry>
    </collision>
    <!-- <cylinder_inertial radius="0.6" length="0.12" mass="${wrist_1_mass}">
        <origin xyz="0.0 0.0 0.0" rpy="0 0 0" />
      </cylinder_inertial> -->
    <inertial>
      <mass value="1.219"/>
      <origin rpy="0.0 0.0 0.0" xyz="0.0 0.110949 0.01634"/>
      <inertia ixx="0.11117275553088" ixy="0.0" ixz="0.0" iyy="0.11117275553088" iyz="0.0" izz="0.21942"/>
    </inertial>
  </link>
  <!-- joint5 connects link4 and link5 -->
  <joint name="ur5_joint5" type="revolute">
    <parent link="ur5_link4"/>
    <child link="ur5_link5"/>
    <origin rpy="0.0 0.0 0.0" xyz="0.0 0.12600000000000003 0.0"/>
    <axis xyz="0 0 1"/>
    <!-- <limit lower="-3.14" upper="3.14" effort="28.0" velocity="3.2" /> -->
    <limit effort="28.0" lower="-3.141592653589793" upper="3.141592653589793" velocity="3.141592653589793"/>
    <dynamics damping="0.3" friction="0.0"/>
  </joint>
  <!-- link 5 -->
  <link name="ur5_link5">
    <visual>
      <geometry>
        <mesh filename="package://ur5_description/meshes/visual/link5.dae"/>
      </geometry>
      <material name="LightGrey">
        <color rgba="0.7 0.7 0.7 1.0"/>
      </material>
    </visual>
    <collision>
      <geometry>
        <mesh filename="package://ur5_description/meshes/collision/link5.stl"/>
      </geometry>
    </collision>
    <!-- <cylinder_inertial radius="0.6" length="0.12" mass="${wrist_2_mass}">
        <origin xyz="0.0 0.0 0.0" rpy="0 0 0" />
      </cylinder_inertial> -->
    <inertial>
      <mass value="1.219"/>
      <origin rpy="0.0 0.0 0.0" xyz="0.0 0.0018 0.11099"/>
      <inertia ixx="0.11117275553088" ixy="0.0" ixz="0.0" iyy="0.11117275553088" iyz="0.0" izz="0.21942"/>
    </inertial>
  </link>
  <!-- joint6 connects link5 and link6 -->
  <joint name="ur5_joint6" type="revolute">
    <parent link="ur5_link5"/>
    <child link="ur5_link6"/>
    <origin rpy="0.0 0.0 0.0" xyz="0.0 0.0 0.1"/>
    <axis xyz="0 1 0"/>
    <!-- <limit lower="-3.14" upper="3.14" effort="28.0" velocity="3.2" /> -->
    <limit effort="28.0" lower="-3.141592653589793" upper="3.141592653589793" velocity="3.141592653589793"/>
    <dynamics damping="0.3" friction="0.0"/>
  </joint>
  <!-- link 6 -->
  <link name="ur5_link6">
    <visual>
      <geometry>
        <mesh filename="package://ur5_description/meshes/visual/link6.dae"/>
      </geometry>
      <material name="LightGrey">
        <color rgba="0.7 0.7 0.7 1.0"/>
      </material>
    </visual>
    <collision>
      <geometry>
        <mesh filename="package://ur5_description/meshes/collision/link6.stl"/>
      </geometry>
    </collision>
    <!-- <cylinder_inertial radius="0.6" length="0.12" mass="${wrist_3_mass}">
        <origin xyz="0.0 0.0 0.0" rpy="0 0 0" />
      </cylinder_inertial> -->
    <inertial>
      <mass value="0.1879"/>
      <origin rpy="0.0 0.0 0.0" xyz="0.0 0.001159 0.0"/>
      <inertia ixx="0.017136473145408" ixy="0.0" ixz="0.0" iyy="0.017136473145408" iyz="0.0" izz="0.033822"/>
    </inertial>
  </link>
  <!-- <joint name="ee_fixed_joint" type="fixed">
      <parent link="$u5_link6" />
      <child link = "ee_link" />
      <origin xyz="0.0 ${wrist_3_length} 0.0" rpy="0.0 0.0 ${pi/2.0}" />
    </joint>

	<link name="ee_link" /> -->
  <!-- link 0 -->
  <gazebo reference="ur5_link0">
    <selfCollide>true</selfCollide>
    <mu1>0.2</mu1>
    <mu2>0.2</mu2>
    <static>true</static>
    <!-- <material>Gazebo/Grey</material> -->
  </gazebo>
  <!-- link/joint 1 -->
  <gazebo reference="ur5_link1">
    <selfCollide>true</selfCollide>
    <mu1>0.2</mu1>
    <mu2>0.2</mu2>
    <!-- <material>Gazebo/White</material> -->
  </gazebo>
  <gazebo reference="ur5_joint1">
    <implicitSpringDamper>1</implicitSpringDamper>
    <provideFeedback>true</provideFeedback>
  </gazebo>
  <!-- link/joint 2 -->
  <gazebo reference="ur5_link2">
    <selfCollide>true</selfCollide>
    <mu1>0.2</mu1>
    <mu2>0.2</mu2>
    <!-- <material>Gazebo/White</material> -->
  </gazebo>
  <gazebo reference="ur5_joint2">
    <implicitSpringDamper>1</implicitSpringDamper>
    <provideFeedback>true</provideFeedback>
  </gazebo>
  <!-- link/joint 3 -->
  <gazebo reference="ur5_link3">
    <selfCollide>true</selfCollide>
    <mu1>0.2</mu1>
    <mu2>0.2</mu2>
    <!-- <material>Gazebo/White</material> -->
  </gazebo>
  <gazebo reference="ur5_joint3">
    <implicitSpringDamper>1</implicitSpringDamper>
    <provideFeedback>true</provideFeedback>
  </gazebo>
  <!-- link/joint 4 -->
  <gazebo reference="ur5_link4">
    <selfCollide>true</selfCollide>
    <mu1>0.2</mu1>
    <mu2>0.2</mu2>
    <!-- <material>Gazebo/White</material> -->
  </gazebo>
  <gazebo reference="ur5_joint4">
    <implicitSpringDamper>1</implicitSpringDamper>
    <provideFeedback>true</provideFeedback>
  </gazebo>
  <!-- link/joint 5 -->
  <gazebo reference="ur5_link5">
    <selfCollide>true</selfCollide>
    <mu1>0.2</mu1>
    <mu2>0.2</mu2>
    <!-- <material>Gazebo/White</material> -->
  </gazebo>
  <gazebo reference="ur5_joint5">
    <implicitSpringDamper>1</implicitSpringDamper>
    <provideFeedback>true</provideFeedback>
  </gazebo>
  <!-- link/joint 6 -->
  <gazebo reference="ur5_link6">
    <selfCollide>true</selfCollide>
    <mu1>0.2</mu1>
    <mu2>0.2</mu2>
    <!-- <material>Gazebo/White</material> -->
  </gazebo>
  <gazebo reference="ur5_joint6">
    <implicitSpringDamper>1</implicitSpringDamper>
    <provideFeedback>true</provideFeedback>
  </gazebo>
  <!-- Load Gazebo lib with desired parameters -->
  <gazebo>
    <plugin filename="libgazebo_ros_control.so" name="gazebo_ros_control">
      <!-- <robotNamespace>/MYROBOT</robotNamespace> -->
    </plugin>
  </gazebo>
  <!-- transmission joint 1 -->
  <transmission name="ur5_tran1">
    <type>transmission_interface/SimpleTransmission</type>
    <joint name="ur5_joint1">
      <hardwareInterface>hardware_interface/PositionJointInterface</hardwareInterface>
    </joint>
    <actuator name="ur5_motor1">
      <hardwareInterface>hardware_interface/PositionJointInterface</hardwareInterface>
      <mechanicalReduction>1</mechanicalReduction>
    </actuator>
  </transmission>
  <!-- transmission joint 2 -->
  <transmission name="ur5_tran2">
    <type>transmission_interface/SimpleTransmission</type>
    <joint name="ur5_joint2">
      <hardwareInterface>hardware_interface/PositionJointInterface</hardwareInterface>
    </joint>
    <actuator name="ur5_motor2">
      <hardwareInterface>hardware_interface/PositionJointInterface</hardwareInterface>
      <mechanicalReduction>1</mechanicalReduction>
    </actuator>
  </transmission>
  <!-- transmission joint 3 -->
  <transmission name="ur5_tran3">
    <type>transmission_interface/SimpleTransmission</type>
    <joint name="ur5_joint3">
      <hardwareInterface>hardware_interface/PositionJointInterface</hardwareInterface>
    </joint>
    <actuator name="ur5_motor3">
      <hardwareInterface>hardware_interface/PositionJointInterface</hardwareInterface>
      <mechanicalReduction>1</mechanicalReduction>
    </actuator>
  </transmission>
  <!-- transmission joint 4 -->
  <transmission name="ur5_tran4">
    <type>transmission_interface/SimpleTransmission</type>
    <joint name="ur5_joint4">
      <hardwareInterface>hardware_interface/PositionJointInterface</hardwareInterface>
    </joint>
    <actuator name="ur5_motor4">
      <hardwareInterface>hardware_interface/PositionJointInterface</hardwareInterface>
      <mechanicalReduction>1</mechanicalReduction>
    </actuator>
  </transmission>
  <!-- transmission joint 5 -->
  <transmission name="ur5_tran5">
    <type>transmission_interface/SimpleTransmission</type>
    <joint name="ur5_joint5">
      <hardwareInterface>hardware_interface/PositionJointInterface</hardwareInterface>
    </joint>
    <actuator name="ur5_motor5">
      <hardwareInterface>hardware_interface/PositionJointInterface</hardwareInterface>
      <mechanicalReduction>1</mechanicalReduction>
    </actuator>
  </transmission>
  <!-- transmission joint 6 -->
  <transmission name="ur5_tran6">
    <type>transmission_interface/SimpleTransmission</type>
    <joint name="ur5_joint6">
      <hardwareInterface>hardware_interface/PositionJointInterface</hardwareInterface>
    </joint>
    <actuator name="ur5_motor6">
      <hardwareInterface>hardware_interface/PositionJointInterface</hardwareInterface>
      <mechanicalReduction>1</mechanicalReduction>
    </actuator>
  </transmission>
</robot>

